2024-08-07 17:05:30,213 INFO    StreamThr :22700 [internal.py:wandb_internal():90] W&B internal server running at pid: 22700, started at: 2024-08-07 17:05:30.212774
2024-08-07 17:05:30,215 DEBUG   HandlerThread:22700 [handler.py:handle_request():144] handle_request: status
2024-08-07 17:05:30,216 INFO    WriterThread:22700 [datastore.py:open_for_write():85] open: C:\Users\Dell\Desktop\DIFUSCO-main\wandb\run-20240807_170530-al5wqm2c\run-al5wqm2c.wandb
2024-08-07 17:05:30,217 DEBUG   SenderThread:22700 [sender.py:send():334] send: header
2024-08-07 17:05:30,217 DEBUG   SenderThread:22700 [sender.py:send():334] send: run
2024-08-07 17:05:31,621 ERROR   SenderThread:22700 [internal_api.py:execute():244] 403 response executing GraphQL.
2024-08-07 17:05:31,621 ERROR   SenderThread:22700 [internal_api.py:execute():245] {"errors":[{"message":"permission denied","path":["upsertBucket"],"extensions":{"code":"PERMISSION_ERROR"}}],"data":{"upsertBucket":null}}
2024-08-07 17:05:32,231 INFO    WriterThread:22700 [datastore.py:close():299] close: C:\Users\Dell\Desktop\DIFUSCO-main\wandb\run-20240807_170530-al5wqm2c\run-al5wqm2c.wandb
2024-08-07 17:05:32,231 INFO    HandlerThread:22700 [handler.py:finish():841] shutting down handler
2024-08-07 17:05:32,231 ERROR   StreamThr :22700 [internal.py:wandb_internal():175] Thread SenderThread:
Traceback (most recent call last):
  File "E:\Program Files (x86)\anaconda\envs\DIFUSCO\lib\site-packages\wandb\sdk\lib\retry.py", line 128, in __call__
    result = self._call_fn(*args, **kwargs)
  File "E:\Program Files (x86)\anaconda\envs\DIFUSCO\lib\site-packages\wandb\sdk\internal\internal_api.py", line 241, in execute
    return self.client.execute(*args, **kwargs)  # type: ignore
  File "E:\Program Files (x86)\anaconda\envs\DIFUSCO\lib\site-packages\wandb\vendor\gql-0.2.0\wandb_gql\client.py", line 52, in execute
    result = self._get_result(document, *args, **kwargs)
  File "E:\Program Files (x86)\anaconda\envs\DIFUSCO\lib\site-packages\wandb\vendor\gql-0.2.0\wandb_gql\client.py", line 60, in _get_result
    return self.transport.execute(document, *args, **kwargs)
  File "E:\Program Files (x86)\anaconda\envs\DIFUSCO\lib\site-packages\wandb\vendor\gql-0.2.0\wandb_gql\transport\requests.py", line 39, in execute
    request.raise_for_status()
  File "E:\Program Files (x86)\anaconda\envs\DIFUSCO\lib\site-packages\requests\models.py", line 1021, in raise_for_status
    raise HTTPError(http_error_msg, response=self)
requests.exceptions.HTTPError: 403 Client Error: Forbidden for url: https://api.wandb.ai/graphql

During handling of the above exception, another exception occurred:

Traceback (most recent call last):
  File "E:\Program Files (x86)\anaconda\envs\DIFUSCO\lib\site-packages\wandb\apis\normalize.py", line 26, in wrapper
    return func(*args, **kwargs)
  File "E:\Program Files (x86)\anaconda\envs\DIFUSCO\lib\site-packages\wandb\sdk\internal\internal_api.py", line 1596, in upsert_run
    **kwargs,
  File "E:\Program Files (x86)\anaconda\envs\DIFUSCO\lib\site-packages\wandb\sdk\internal\internal_api.py", line 216, in gql
    **kwargs,
  File "E:\Program Files (x86)\anaconda\envs\DIFUSCO\lib\site-packages\wandb\sdk\lib\retry.py", line 144, in __call__
    retry_timedelta_triggered = check_retry_fn(e)
  File "E:\Program Files (x86)\anaconda\envs\DIFUSCO\lib\site-packages\wandb\util.py", line 1065, in check_retry_fn
    return fallback_retry_fn(e)
  File "E:\Program Files (x86)\anaconda\envs\DIFUSCO\lib\site-packages\wandb\util.py", line 1012, in no_retry_auth
    raise CommError("Permission denied, ask the project owner to grant you access")
wandb.errors.CommError: Permission denied, ask the project owner to grant you access

During handling of the above exception, another exception occurred:

Traceback (most recent call last):
  File "E:\Program Files (x86)\anaconda\envs\DIFUSCO\lib\site-packages\wandb\sdk\internal\internal_util.py", line 49, in run
    self._run()
  File "E:\Program Files (x86)\anaconda\envs\DIFUSCO\lib\site-packages\wandb\sdk\internal\internal_util.py", line 100, in _run
    self._process(record)
  File "E:\Program Files (x86)\anaconda\envs\DIFUSCO\lib\site-packages\wandb\sdk\internal\internal.py", line 329, in _process
    self._sm.send(record)
  File "E:\Program Files (x86)\anaconda\envs\DIFUSCO\lib\site-packages\wandb\sdk\internal\sender.py", line 341, in send
    send_handler(record)
  File "E:\Program Files (x86)\anaconda\envs\DIFUSCO\lib\site-packages\wandb\sdk\internal\sender.py", line 927, in send_run
    self._init_run(run, config_value_dict)
  File "E:\Program Files (x86)\anaconda\envs\DIFUSCO\lib\site-packages\wandb\sdk\internal\sender.py", line 969, in _init_run
    commit=run.git.commit or None,
  File "E:\Program Files (x86)\anaconda\envs\DIFUSCO\lib\site-packages\wandb\apis\normalize.py", line 64, in wrapper
    raise CommError(message, err).with_traceback(sys.exc_info()[2])
  File "E:\Program Files (x86)\anaconda\envs\DIFUSCO\lib\site-packages\wandb\apis\normalize.py", line 26, in wrapper
    return func(*args, **kwargs)
  File "E:\Program Files (x86)\anaconda\envs\DIFUSCO\lib\site-packages\wandb\sdk\internal\internal_api.py", line 1596, in upsert_run
    **kwargs,
  File "E:\Program Files (x86)\anaconda\envs\DIFUSCO\lib\site-packages\wandb\sdk\internal\internal_api.py", line 216, in gql
    **kwargs,
  File "E:\Program Files (x86)\anaconda\envs\DIFUSCO\lib\site-packages\wandb\sdk\lib\retry.py", line 144, in __call__
    retry_timedelta_triggered = check_retry_fn(e)
  File "E:\Program Files (x86)\anaconda\envs\DIFUSCO\lib\site-packages\wandb\util.py", line 1065, in check_retry_fn
    return fallback_retry_fn(e)
  File "E:\Program Files (x86)\anaconda\envs\DIFUSCO\lib\site-packages\wandb\util.py", line 1012, in no_retry_auth
    raise CommError("Permission denied, ask the project owner to grant you access")
wandb.errors.CommError: Permission denied, ask the project owner to grant you access
